Workbook

Sheet Trial Balance
B2: Trial Balance
A3: សំរាប់ខែ Sep
A5: Note | B5: A/c Code | D5: Description | E5: Debit | F5: Credit | G5: Year to date Last month | I5: Year to date Current month
G6: Debit | H6: Credit | I6: Debit | J6: Credit
A7: BS | B7: 10000 | D7: ទ្រព្យ
A8: BS | B8: 11000 | D8: សាច់ប្រាក់
A9: BS | C9: 11001 | D9: សាច់ប្រាក់នៅបេលា | I9: =E9 -> 0 | J9: =F9 -> 0
A10: BS | C10: 11002 | D10: សាច់ប្រាក់នៅធនាគា ACLEDA | E10: 2213 | I10: =E10 -> 2213 | J10: =F10 -> 0
A11: BS | C11: 11003 | D11: សាច់ប្រាក់នៅធនាគា ABA | I11: =E11 -> 0 | J11: =F11 -> 0
A12: BS | I12: =E12 -> 0 | J12: =F12 -> 0
A13: BS | B13: 12000 | D13: គណនីត្រូវទទូលបាន​(គេជំពាក់យើង) | I13: =E13 -> 0 | J13: =F13 -> 0
A14: BS | C14: 12001 | D14: បុគ្គលិកជំពាក់ | E14: 50 | I14: =E14 -> 50 | J14: =F14 -> 0
A15: BS | C15: 12002 | D15: អតិថិជនជំពាក់ | I15: =E15 -> 0 | J15: =F15 -> 0
A16: BS | C16: 12003 | D16: គណនីត្រូវទទូលផ្សេងៗ | I16: =E16 -> 0 | J16: =F16 -> 0
A17: BS | I17: =E17 -> 0 | J17: =F17 -> 0
A18: BS | B18: 13000 | D18: ស្តុកថ្មី | I18: =E18 -> 0 | J18: =F18 -> 0
A19: BS | C19: 13110 | D19: ម៉ាស៊ីនត្រជាក់ជាប់ជញ្ជាំង Panasonic | E19: 906.67 | I19: =E19 -> 906.67 | J19: =F19 -> 0
A20: BS | C20: 13120 | D20: ម៉ាស៊ីនត្រជាក់ជាប់ពិដាន Panasonic | I20: =E20 -> 0 | J20: =F20 -> 0
A21: BS | C21: 13130 | D21: ម៉ាស៊ីនត្រជាក់បញ្ឈរ Panasonic | I21: =E21 -> 0 | J21: =F21 -> 0
A22: BS | C22: 13210 | D22: ម៉ាស៊ីនត្រជាក់ជាប់ជញ្ជាំង Daikin | I22: =E22 -> 0 | J22: =F22 -> 0
A23: BS | C23: 13220 | D23: ម៉ាស៊ីនត្រជាក់ជាប់ពិដាន Daikin | I23: =E23 -> 0 | J23: =F23 -> 0
A24: BS | C24: 13230 | D24: ម៉ាស៊ីនត្រជាក់បញ្ឈរ Daikin | I24: =E24 -> 0 | J24: =F24 -> 0
A25: BS | C25: 13310 | D25: ម៉ាស៊ីនត្រជាក់ជាប់ជញ្ជាំង LG | I25: =E25 -> 0 | J25: =F25 -> 0
A26: BS | C26: 13320 | D26: ម៉ាស៊ីនត្រជាក់ជាប់ពិដាន LG | I26: =E26 -> 0 | J26: =F26 -> 0
A27: BS | C27: 13330 | D27: ម៉ាស៊ីនត្រជាក់បញ្ឈរ LG | I27: =E27 -> 0 | J27: =F27 -> 0
A28: BS | C28: 13310 | D28: ម៉ាស៊ីនត្រជាក់ជាប់ជញ្ជាំង Gree | I28: =E28 -> 0 | J28: =F28 -> 0
A29: BS | C29: 13320 | D29: ម៉ាស៊ីនត្រជាក់ជាប់ពិដាន Gree | I29: =E29 -> 0 | J29: =F29 -> 0
A30: BS | C30: 13330 | D30: ម៉ាស៊ីនត្រជាក់បញ្ឈរ Gree | I30: =E30 -> 0 | J30: =F30 -> 0
A31: BS | C31: 13400 | D31: ទុយោស្ពាន់ | I31: =E31 -> 0 | J31: =F31 -> 0
A32: BS | C32: 13500 | D32: ហ្គេនទុយោស្ពាន់ | E32: 238.96 | I32: =E32 -> 238.96 | J32: =F32 -> 0
A33: BS | C33: 13600 | D33: ប្រអប់ខ្សែភ្លើង | I33: =E33 -> 0 | J33: =F33 -> 0
A34: BS | C34: 13700 | D34: ខ្សែភ្លើង | I34: =E34 -> 0 | J34: =F34 -> 0
A35: BS | C35: 14100 | D35: ម៉ាស៊ីនបោកខោអាវ | I35: =E35 -> 0 | J35: =F35 -> 0
A36: BS | C36: 14200 | D36: ទូទឹកកក | I36: =E36 -> 0 | J36: =F36 -> 0
A37: BS | C37: 14300 | D37: ម៉ូទ័រជុំរុញទឹក | I37: =E37 -> 0 | J37: =F37 -> 0
A38: BS | C38: 14400 | D38: (ឆ្នាំងបាយ,កង្ហា,ម៉ាស៊ីនទឹកក្តៅទឹកត្រជាក់....) | I38: =E38 -> 0 | J38: =F38 -> 0
A39: BS | C39: 14500 | D39: សម្ភារះសម្រាប់ជាងប្រប្រាស់ | I39: =E39 -> 0 | J39: =F39 -> 0
I40: =E40 -> 0 | J40: =F40 -> 0
A41: BS | B41: 18000 | D41: ស្តុក Second hand | I41: =E41 -> 0 | J41: =F41 -> 0
A42: BS | C42: 18100 | D42: ម៉ាស៊ីនត្រជាក់ | I42: =E42 -> 0 | J42: =F42 -> 0
...

Sheet Income Statment
B3: របាយការណ៍ចំណេញ/(ខាត)
B4: សំរាប់ខែ Sep
B5: ចំណូល | D5: Current month | E5: Last Month | F5: Year to Date Last month | G5: Year to Date 202​​6 (ខែ1,2,3,4,5,6,7,8,9)
B7: 40001 | C7: ចំណូលពីការលក់
B8: 40002 | C8: ចំណូលពីការសេវាកម្ម
B9: 40004 | C9: ចំណូលពីការលក់ (ក្នុងបូរី) | D9: ='Trial Balance'!F62 -> 1298
B10: 40005 | C10: ចំណូលពីការសេវាកម្ម (ក្នុងបូរី) | D10: ='Trial Balance'!F63 -> 75
B11: 40006 | C11: ចំណូលផ្សេងៗ
B13: ចំណូលសរុប | D13: =SUM(D7:D12) -> 1373 | E13: =SUM(E7:E12) -> 0 | F13: =SUM(F7:F12) -> 0 | G13: =F13+D13 -> 1373
B15: 50001 | C15: ចំណាយទៅលើថ្លៃដើម | D15: ='Trial Balance'!E67 -> 1054.37
B17: ចំណេញដុល | D17: =D13-D15-D16 -> 318.63 | E17: =E13-E15-E16 -> 0 | F17: =F13-F15-F16 -> 0 | G17: =F17+D17 -> 318.63
B19: ចំណាយ
B20: 50002 | C20: ចំណាយប្រាក់ខែបុគ្គលិក
B21: 50003 | C21: អត្ថប្រយោជន៍បន្ថែមទៅបុគ្គលិក
B22: 50004 | C22: ចំណាយសំរាប់សំភារៈការិយាល័យ
B23: 50005 | C23: សំភារះជាងប្រើប្រាស់
B24: 50006 | C24: ចំណាយជួល Office
B25: 50007 | C25: ចំណាយទឹកភ្លើង
B26: 50008 | C26: ចំណាយ​ជូសជុល Office
B27: 50009 | C27: ចំណាយទៅលើការផ្សោះផ្សាយ
B28: 50010 | C28: ចំណាយ​ទៅលើកាធ្វើដំណើរ
B29: 50011 | C29: ចំណាយ​ផ្សេងៗ
B30: 50012 | C30: ចំណាយ​បញ្ចុះតម្លៃ | D30: ='Trial Balance'!E78 -> 10
B32: ចំណាយសរុប | D32: =SUM(D20:D30) -> 10 | E32: =SUM(E20:E28) -> 0 | F32: =SUM(F20:F28) -> 0 | G32: =F32+D32 -> 10
F33: 0 | G33: =F33+D33 -> 0
B34: ចំណេញ/​ខាត​(-) | D34: =D17-D32 -> 308.63 | E34: =E17-E32 -> 0 | F34: =F17-F32 -> 0 | G34: =F34+D34 -> 308.63

Sheet Balance sheet
B3: Balance Sheet
B4: សំរាប់ខែ Sep
B6: ទ្រព្យ | D6: Current Month | E6: Last Month | F6: Difference
B7: 11001 | C7: សាច់ប្រាក់នៅបេលា
B8: 11002 | C8: សាច់ប្រាក់នៅធនាគា ACLEDA | D8: ='Trial Balance'!E10 -> 2213
B9: 11003 | C9: សាច់ប្រាក់នៅធនាគា ABA
B10: 12001 | C10: បុគ្គលិកជំពាក់ | D10: ='Trial Balance'!E14 -> 50
B11: 12002 | C11: អតិថិជនជំពាក់
B12: 12003 | C12: គណនីត្រូវទទូលផ្សេងៗ
B13: 13110 | C13: ម៉ាស៊ីនត្រជាក់ជាប់ជញ្ជាំង Panasonic | D13: ='Trial Balance'!E19 -> 906.67
B14: 13120 | C14: ម៉ាស៊ីនត្រជាក់ជាប់ពិដាន Panasonic
B15: 13130 | C15: ម៉ាស៊ីនត្រជាក់បញ្ឈរ Panasonic
B16: 13210 | C16: ម៉ាស៊ីនត្រជាក់ជាប់ជញ្ជាំង Daikin
B17: 13220 | C17: ម៉ាស៊ីនត្រជាក់ជាប់ពិដាន Daikin
B18: 13230 | C18: ម៉ាស៊ីនត្រជាក់បញ្ឈរ Daikin
B19: 13310 | C19: ម៉ាស៊ីនត្រជាក់ជាប់ជញ្ជាំង LG
B20: 13320 | C20: ម៉ាស៊ីនត្រជាក់ជាប់ពិដាន LG
B21: 13330 | C21: ម៉ាស៊ីនត្រជាក់បញ្ឈរ LG
B22: 13310 | C22: ម៉ាស៊ីនត្រជាក់ជាប់ជញ្ជាំង Gree
B23: 13320 | C23: ម៉ាស៊ីនត្រជាក់ជាប់ពិដាន Gree
B24: 13330 | C24: ម៉ាស៊ីនត្រជាក់បញ្ឈរ Gree
B25: 13400 | C25: ទុយោស្ពាន់
B26: 13500 | C26: ហ្គេនទុយោស្ពាន់ | D26: ='Trial Balance'!E32 -> 238.96
B27: 13600 | C27: ប្រអប់ខ្សែភ្លើង
B28: 13700 | C28: ខ្សែភ្លើង
B29: 14100 | C29: ម៉ាស៊ីនបោកខោអាវ
B30: 14200 | C30: ទូទឹកកក
B31: 14300 | C31: ម៉ូទ័រជុំរុញទឹក
B32: 14400 | C32: (ឆ្នាំងបាយ,កង្ហា,ម៉ាស៊ីនទឹកក្តៅទឹកត្រជាក់....)
B33: 14500 | C33: សម្ភារះសម្រាប់ជាងប្រប្រាស់
B34: 18100 | C34: ម៉ាស៊ីនត្រជាក់
B35: 18200 | C35: ម៉ាស៊ីនបោកខោអាវ
B36: 18300 | C36: ទូទឹកកក
B37: 18400 | C37: ម៉ូទ័រជុំរុញទឹក
B39: ទ្រព្យសរុប | D39: =SUM(D7:D38) -> 3408.63 | E39: =SUM(E7:E38) -> 0 | F39: =SUM(F7:F38) -> 0
B41: បំណុល
B42: 20001 | C42: ជំពាក់ថ្លៃម៉ាស៊ីនត្រជាក់
B43: 20002 | C43: ជំពាក់ម៉ាស៊ីនបោកក់
B44: 20003 | C44: ជំពាក់ទៅអ្នកផ្គត់ផ្គង់ផ្សេងៗ
B45: 20004 | C45: អតិថិជនកក់
...
